Workbook

Sheet 100k
A1: Lr | B1: 2e-05 | C1: Lm | D1: =B1*D2 -> 0.0004
A2: Cr | B2: =1/((2*PI()*B7)^2*B1) -> 1.4072387e-06 | C2: k | D2: 20
A3: Rac | B3: =Sheet2!$D$4 -> 8.1056947 | C3: Q | D3: =SQRT(B1/B2)/B3 -> 0.46509415 | G3: 6 | H3: 0.314159
G4: 5 | H4: 0.376991
A5: fn | C5: changing | G5: 4 | H5: 0.471239
A6: fs | C6: 1-60k
A7: fr | B7: 30000
A9: 1/13/2025 with focus on Lm
A10: Lr | B10: =D10/D11 -> 1.998795e-05 | C10: Lm | D10: =D13*(1/B16/2-D13)/(4*(G10+G10+G11)) -> 0.00039975901 | F10: Coss | G10: 3e-10
A11: Cr | B11: =1/((2*PI()*B16)^2*B10) -> 1.408087e-06 | C11: k | D11: 20 | F11: Cw | G11: 3e-10
A12: Rac | B12: =Sheet2!$D$4 -> 8.1056947 | C12: Q | D12: =SQRT(B10/B11)/B12 -> 0.46481394 | G12: 6 | H12: 0.314159
C13: dt | D13: 8.68e-08 | G13: 5 | H13: 0.376991
A14: fn | C14: changing | G14: 4 | H14: 0.471239
A15: fs | C15: 1-60k | M15: =1/(2*PI()*SQRT(0.00007292*0.00000003473)) -> 100010.23
A16: fr | B16: 30000 | D16: =1/(2*PI()*SQRT(B10*B11)) -> 30000
A19: 1/13/2025 with focus on Lm
A20: Lr | B20: =0.0000344 -> 3.44e-05 | C20: Lm | D20: =D23*(1/B26/2-D23)/(4*(G20+G20+G21)) -> 0.00068819444 | F20: Coss | G20: 3e-10
A21: Cr | B21: =1/((2*PI()*B26)^2*B20) -> 8.1816201e-07 | C21: k | D21: 20 | F21: Cw | G21: 3e-10
A22: Rac | B22: =Sheet2!$D$4 -> 8.1056947 | C22: Q | D22: =SQRT(B20/B21)/B22 -> 0.79996194 | E22: =SQRT(B20/B21)/B22 -> 0.79996194 | G22: 6 | H22: 0.314159
C23: dt | D23: 1.5e-07 | G23: 5 | H23: 0.376991
A24: fn | C24: changing | G24: 4 | H24: 0.471239
A25: fs | C25: 1-60k
A26: fr | B26: 30000 | D26: =1/(2*PI()*SQRT(B20*B21)) -> 30000
A28: 1/13/2025 with focus on Lm
A29: Lr | B29: =0.0000344 -> 3.44e-05 | C29: Lm | D29: =D32*(1/B35/2-D32)/(4*(G29+G29+G30)) -> 0.00034382449 | F29: Coss | G29: 3e-10
A30: Cr | B30: =1/((2*PI()*B35)^2*B29) -> 8.1816201e-07 | C30: k | D30: 10 | F30: Cw | G30: 3e-10
A31: Rac | B31: =Sheet2!$D$4 -> 8.1056947 | C31: Q | D31: =SQRT(B29/B30)/B31 -> 0.79996194 | E31: =SQRT(B29/B30)/B31 -> 0.79996194 | G31: 6 | H31: 0.314159
C32: dt | D32: 7.46e-08 | G32: 5 | H32: 0.376991
A33: fn | C33: changing | G33: 4 | H33: 0.471239
A34: fs | C34: 1-60k
A35: fr | B35: 30000 | D35: =1/(2*PI()*SQRT(B29*B30)) -> 30000
A39: 1/13/2025 with focus on Lm
A40: Lr | B40: =0.0000344 -> 3.44e-05 | C40: Lm | D40: =D43*(1/B46/2-D43)/(4*(G40+G40+G41)) -> 0.00034382449 | F40: Coss | G40: 3e-10
A41: Cr | B41: =1/((2*PI()*B46)^2*B40) -> 8.1816201e-07 | C41: k | D41: 10 | F41: Cw | G41: 3e-10
A42: Rac | B42: =Sheet2!$D$4 -> 8.1056947 | C42: Q | D42: =SQRT(B40/B41)/B42 -> 0.79996194 | E42: =SQRT(B40/B41)/B42 -> 0.79996194 | G42: 6 | H42: 0.314159
C43: dt | D43: 7.46e-08 | G43: 5 | H43: 0.376991
A44: fn | C44: changing | G44: 4 | H44: 0.471239
A45: fs | C45: 1-60k
A46: fr | B46: 30000 | D46: =1/(2*PI()*SQRT(B40*B41)) -> 30000
H48: =20*6.25 -> 125
...

Sheet Final
A1: 100 kW
A2: Lr | B2: 2e-05 | C2: Lm | D2: =B2*D3 -> 0.0006 | E2: Lmax | F2: =D5*(1/B8/2-D5)/(4*(D6+D7+D7)) -> 0.00091481481
A3: Cr | B3: =1/((2*PI()*B8)^2*B2) -> 1.4072387e-06 | C3: k | D3: 30
A4: Rac | B4: =Sheet2!$D$4 -> 8.1056947 | C4: Q | D4: =SQRT(B2/B3)/B4 -> 0.46509415
C5: dt | D5: 2e-07
A6: fn | C6: Coss | D6: 3e-10
A7: fs | C7: Cw | D7: 3e-10
A8: fr | B8: 30000
R10: new
A11: 200 kW | J11: 200 kW | R11: 200 kW
A12: Lr | B12: 1e-05 | C12: Lm | D12: =B12*D13 -> 0.0003 | E12: Lmax | F12: =D18*(1/B20/2-D18)/(4*(D19+D20+D20)) -> 0.0030169753 | J12: Lr | K12: =1/((2*PI()*K23)^2*K13) -> 1.1257909e-05 | L12: Lm | M12: =K12*M13 -> 0.00013509491 | N12: Lmax | O12: =M20/(16*M21*4*K23) -> 0.00034722222 | R12: Lr | S12: =1/((2*PI()*B21)^2*S13) -> 5.0035152e-05 | T12: Lm | U12: =S12*U13 -> 0.0025017576 | V12: Lmax | W12: =U18*(1/S20/2-U18)/(4*(U19+U20+U20)) -> #DIV/0!
A13: Cr | B13: =1/((2*PI()*B21)^2*B12) -> 5.0035152e-06 | C13: k | D13: 30 | H13: =1/((2*PI()*K23)^2*K11) -> #DIV/0! | J13: Cr | K13: 2.5e-06 | L13: k | M13: 12 | N13: Ip, rms | O13: =1000^2/8*(((1/K22)/(2*M12))^2+(PI()/Sheet2!C4)^2) -> 15719.266 | R13: Cr | S13: 1e-06 | T13: k | U13: 50
A14: Rac 100k | B14: =Sheet2!$D4 -> 8.1056947 | C14: Q 100k | D14: =SQRT($B$12/$B$13)/$B14 -> 0.17441031 | J14: Rac10k | K14: =Sheet2!D6 -> 81.056947 | L14: Q10k | M14: =SQRT(K$12/K$13)/$K14 -> 0.026179939 | N14: Is, rms | R14: Rac 100k | S14: =Sheet2!$D4 -> 8.1056947 | T14: Q 100k | U14: =SQRT($S$12/$S$13)/$S14 -> 0.87266463
A15: Rac 200k | B15: =Sheet2!$D3 -> 4.0528473 | C15: Q 200k | D15: =SQRT($B$12/$B$13)/$B15 -> 0.34882061 | J15: Rac50k | K15: =Sheet2!D5 -> 16.211389 | L15: Q50k | M15: =SQRT(K$12/K$13)/$K15 -> 0.13089969 | R15: Rac 200k | S15: =Sheet2!$D3 -> 4.0528473 | T15: Q 200k | U15: =SQRT($S$12/$S$13)/$S15 -> 1.7453293
A16: Rac 300k | B16: =Sheet2!$D2 -> 2.7018982 | C16: Q 300k | D16: =SQRT($B$12/$B$13)/$B16 -> 0.52323092 | J16: Rac 100k | K16: =Sheet2!$D4 -> 8.1056947 | L16: Q 100k | M16: =SQRT(K$12/K$13)/$B14 -> 0.26179939 | R16: Rac 300k | S16: =Sheet2!$D2 -> 2.7018982 | T16: Q 300k | U16: =SQRT($S$12/$S$13)/$S16 -> 2.6179939
J17: Rac 200k | K17: =Sheet2!$D3 -> 4.0528473 | L17: Q 200k | M17: =SQRT(K$12/K$13)/$B15 -> 0.52359878
C18: dt | D18: 5e-07 | J18: Rac 300k | K18: =Sheet2!$D2 -> 2.7018982 | L18: Q 300k | M18: =SQRT(K$12/K$13)/$B16 -> 0.78539816
A19: fn | C19: Coss | D19: 3e-10
A20: fs | B20: 22500 | C20: Cw | D20: 3e-10 | L20: dt | M20: 2e-07
A21: fr | B21: 22500 | J21: fn | L21: Coss | M21: 3e-10
A22: fn | B22: =B20/B21 -> 1 | J22: fs | K22: 22500 | L22: Cw | M22: 3e-10
J23: fr | K23: 30000
J24: fn | K24: =K23/K22 -> 1.3333333

Sheet Presentation Material
A1: 100 kW
A2: Lr | B2: 2e-05 | C2: Lm | D2: =B2*D3 -> 0.0006 | E2: Lmax | F2: =D5*(1/B8/2-D5)/(4*(D6+D7+D7)) -> 0.00091481481
A3: Cr | B3: =1/((2*PI()*B8)^2*B2) -> 1.4072387e-06 | C3: k | D3: 30
A4: Rac | B4: =Sheet2!$D$4 -> 8.1056947 | C4: Q | D4: =SQRT(B2/B3)/B4 -> 0.46509415
C5: dt | D5: 2e-07
A6: fn | C6: Coss | D6: 3e-10
A7: fs | C7: Cw | D7: 3e-10
A8: fr | B8: 30000
R10: new
A11: 200 kW | J11: 200 kW | R11: 200 kW
A12: Lr | B12: 1e-05 | C12: Lm | D12: =B12*D13 -> 0.0003 | E12: Lmax | F12: =D18*(1/B20/2-D18)/(4*(D19+D20+D20)) -> 0.0030169753 | J12: Lr | K12: =1/((2*PI()*K23)^2*K13) -> 6.8518129e-06 | L12: Lm | M12: =K12*M13 -> 0.00010277719 | N12: Lmax | O12: =M20/(16*M21*4*K23) -> 0.00048076923 | R12: Lr | S12: =1/((2*PI()*B21)^2*S13) -> 5.0035152e-05 | T12: Lm | U12: =S12*U13 -> 0.0025017576 | V12: Lmax | W12: =U18*(1/S20/2-U18)/(4*(U19+U20+U20)) -> #DIV/0!
A13: Cr | B13: =1/((2*PI()*B21)^2*B12) -> 5.0035152e-06 | C13: k | D13: 30 | H13: =1/((2*PI()*K23)^2*K11) -> #DIV/0! | J13: Cr | K13: 3.5e-06 | L13: k | M13: 15 | N13: Ip, rms | O13: =(1000^2/8*(((1/K22)/(2*M12))^2+(PI()/Sheet2!C2)^2))^0.5 -> 339.03537 | P13: =O13*SQRT(2) -> 479.46841 | R13: Cr | S13: 1e-06 | T13: k | U13: 50
A14: Rac 100k | B14: =Sheet2!$D4 -> 8.1056947 | C14: Q 100k | D14: =SQRT($B$12/$B$13)/$B14 -> 0.17441031 | J14: Rac10k | K14: =Sheet2!D6 -> 81.056947 | L14: Q10k | M14: =SQRT(K$12/K$13)/$K14 -> 0.017261498 | N14: Is, rms | R14: Rac 100k | S14: =Sheet2!$D4 -> 8.1056947 | T14: Q 100k | U14: =SQRT($S$12/$S$13)/$S14 -> 0.87266463
A15: Rac 200k | B15: =Sheet2!$D3 -> 4.0528473 | C15: Q 200k | D15: =SQRT($B$12/$B$13)/$B15 -> 0.34882061 | J15: Rac50k | K15: =Sheet2!D5 -> 16.211389 | L15: Q50k | M15: =SQRT(K$12/K$13)/$K15 -> 0.08630749 | R15: Rac 200k | S15: =Sheet2!$D3 -> 4.0528473 | T15: Q 200k | U15: =SQRT($S$12/$S$13)/$S15 -> 1.7453293
A16: Rac 300k | B16: =Sheet2!$D2 -> 2.7018982 | C16: Q 300k | D16: =SQRT($B$12/$B$13)/$B16 -> 0.52323092 | J16: Rac 100k | K16: =Sheet2!$D4 -> 8.1056947 | L16: Q 100k | M16: =SQRT(K$12/K$13)/$B14 -> 0.17261498 | R16: Rac 300k | S16: =Sheet2!$D2 -> 2.7018982 | T16: Q 300k | U16: =SQRT($S$12/$S$13)/$S16 -> 2.6179939
J17: Rac 200k | K17: =Sheet2!$D3 -> 4.0528473 | L17: Q 200k | M17: =SQRT(K$12/K$13)/$B15 -> 0.34522996
C18: dt | D18: 5e-07 | J18: Rac 300k | K18: =Sheet2!$D2 -> 2.7018982 | L18: Q 300k | M18: =SQRT(K$12/K$13)/$B16 -> 0.51784494
A19: fn | C19: Coss | D19: 3e-10
A20: fs | B20: 22500 | C20: Cw | D20: 3e-10 | L20: dt | M20: 3e-07
A21: fr | B21: 22500 | J21: fn | L21: Coss | M21: 3e-10 | O21: =150/68.5 -> 2.189781
A22: fn | B22: =B20/B21 -> 1 | J22: fs | K22: 27500 | L22: Cw | M22: 3e-10
J23: fr | K23: 32500
J24: fn | K24: =K22/K23 -> 0.84615385

Sheet Sheet2
A1: Po | B1: Vo | C1: Ro | D1: Rac | E1: Q
A2: 300000 | B2: 1000 | C2: =B2^2/A2 -> 3.3333333 | D2: =8/(PI())^2*C2 -> 2.7018982 | E2: =SQRT('100k'!$B$1/'100k'!$B$2)/Sheet2!D2 -> 1.3952825
A3: 200000 | B3: 1000 | C3: =B3^2/A3 -> 5 | D3: =8/(PI())^2*C3 -> 4.0528473
A4: 100000 | B4: 1000 | C4: =B4^2/A4 -> 10 | D4: =8/(PI())^2*C4 -> 8.1056947 | E4: =SQRT('100k'!$B$1/'100k'!$B$2)/Sheet2!D4 -> 0.46509415
A5: 50000 | B5: 1000 | C5: =B5^2/A5 -> 20 | D5: =8/PI()^2*C5 -> 16.211389 | E5: =SQRT('100k'!$B$1/'100k'!$B$2)/Sheet2!D5 -> 0.23254708
A6: 10000 | B6: 1000 | C6: =B6^2/A6 -> 100 | D6: =8/PI()^2*C6 -> 81.056947 | E6: =SQRT('100k'!$B$1/'100k'!$B$2)/Sheet2!D6 -> 0.046509415
A7: 5000 | B7: 1000 | C7: =B7^2/A7 -> 200 | D7: =8/PI()^2*C7 -> 162.11389 | E7: =SQRT('100k'!$B$1/'100k'!$B$2)/Sheet2!D7 -> 0.023254708
A8: 1000 | B8: 1000 | C8: =B8^2/A8 -> 1000 | D8: =8/PI()^2*C8 -> 810.56947 | E8: =SQRT('100k'!$B$1/'100k'!$B$2)/Sheet2!D8 -> 0.0046509415
A9: 500 | B9: 1000 | C9: =B9^2/A9 -> 2000 | D9: =8/PI()^2*C9 -> 1621.1389 | E9: =SQRT('100k'!$B$1/'100k'!$B$2)/Sheet2!D9 -> 0.0023254708
A10: 100 | B10: 1000 | C10: =B10^2/A10 -> 10000 | D10: =8/PI()^2*C10 -> 8105.6947 | E10: =SQRT('100k'!$B$1/'100k'!$B$2)/Sheet2!D10 -> 0.00046509415

Sheet Transformer Parameters 10 turns
A1: Let's discuss using max power
A2: Po | B2: output power | C2: 300000 | E2: Ip, rms | F2: primary side current, rms | G2: =SQRT((C3^2/8)*(((1/C6)/(2*C11))^2+(PI()/C5)^2)) -> 335.86395 | H2: =SQRT(2)/2*(PI())*300000/1000+1000/(4*150*10^-6*30000) -> 721.988 | I2: phase difference | K2: =ASIN((C3*1/C6)/(4*SQRT(2)*C11*G2)) -> 0.12564802 | M2: =K2*180/PI() -> 7.1991015
A3: Vo | B3: output voltage | C3: 1000 | E3: Is, rms | F3: secondary side current, rms | G3: =G2 -> 335.86395 | I3: time difference | K3: =K2/(2*PI()*C6) -> 7.1419658e-07
A4: Io | B4: output current | C4: =C2/C3 -> 300 | E4: Ip, pk | F4: primary side current, pk | G4: =G2*SQRT(2) -> 474.98335 | H4: =SQRT(2)/2*(PI())*300000/1000+1000/(4*150*10^-6*27000) -> 728.16084 | O4: =ASIN((C3*1/C6)/(4*SQRT(2)*C11*G2)) -> 0.12564802
A5: Ro | B5: output resistance | C5: =C3/C4 -> 3.3333333 | E5: Is, pk | F5: secondary side current, pk | G5: =G3*SQRT(2) -> 474.98335 | H5: =SQRT(2)/2*(PI())*300000/1000 -> 666.43244
A6: fs | B6: switching frequency | C6: 28000 | E6: dt | F6: deadtime | K6: =4*2*PI()*C6*10^-7 -> 0.070371675
A7: fr | B7: resonant frequency | C7: 30000
A8: phi | B8: phase diff
A9: Transformer Parameters
A10: number of turns | B10: n | C10: =C11*C13/(C12*E11) -> 7.5 | D10: actual chosen | E10: 10
A11: magnetizing inductance | B11: Lm | C11: 0.00015 | D11: max saturation flux density | E11: 0.4
A12: area of center leg | B12: Ac | C12: =C23 -> 0.025 | F12: =1/3*10^-4 -> 3.3333333e-05
A13: Ipri, pk | B13: Ip, pk (estimate) | C13: 500 | E13: =10^2*2500*4*PI()*10^-7*C12/0.12 -> 0.065449847
A14: Area Product | B14: theoretical | D14: actual
A15: AwAc | B15: =B16*B17 -> 29462783 | D15: =D23*220*26 -> 143000000 | L15: =145944*3 -> 437832
A16: Aw | B16: =(10/(5*0.9)*(500/SQRT(2))*2) -> 1571.3484
A17: Ac | B17: =(C11*500)/(10*0.4)*10^6 -> 18750
A19: Transformer Dimensions | D19: mm | G19: path modelling
A20: nCore | B20: number of cores | C20: 5 | F20: half cross section | G20: =D30/2+B31+B32 -> 5.5 | I20: #1 | J20: =D22+1*G21 -> 111
A21: L_c | B21: length of center leg | C21: =250/1000 -> 0.25 | D21: =1000*C21 -> 250 | F21: whole cross section | G21: =G20*2 -> 11 | I21: #2 | J21: =D21+2*G21 -> 272
A22: W_c | B22: width of center leg | C22: =100/1000 -> 0.1 | D22: =1000*C22 -> 100 | I22: #3 | J22: =D22+G21*2 -> 122
A23: A_c | B23: area of center leg | C23: =C21*C22 -> 0.025 | D23: =1000*C23*1000 -> 25000 | I23: #4 | J23: =D21+G21*4 -> 294
A24: A_l | B24: area of right and left leg | C24: =C23/2 -> 0.0125 | D24: =1000*C24*1000 -> 12500 | I24: #5 | J24: =D22+3*G21+G21 -> 144
A25: L_l | B25: length of right and left leg | C25: =C21 -> 0.25 | D25: =1000*C25 -> 250 | I25: #6 | J25: =D21+6*G21 -> 316
A26: W_l | B26: width of right and left leg | C26: =C22/2 -> 0.05 | D26: =1000*C26 -> 50 | I26: #7 | J26: =D22+6*G21 -> 166
I27: #8 | J27: =D21+8*G21 -> 338
A28: Wire Dimensions | I28: #9
A29: Wire Height | B29: 12.5 | D29: 20 | E29: 25 | I29: #10
A30: Wire Width | B30: 8 | D30: 5 | E30: 4 | I30: #11
A31: wire coating thickness | B31: 2 | I31: #12
A32: insulation thickness | B32: 1 | I32: #13
I33: #14
I34: #15
A37: air gap | B37: =(E10^2*B40*B41*C23^2/C11-C23*(B38+B39))*1/((B41-1)*2*C23)*10^3 -> 10.278887
A38: lmc | B38: 0.36
A39: lmo | B39: 0.626
A40: uo | B40: =4*PI()*10^-7 -> 1.2566371e-06
A41: ur | B41: 2500

Sheet Transformer Parameters8 turns
A1: Let's discuss using max power
A2: Po | B2: output power | C2: 300000 | E2: Ip, rms | F2: primary side current, rms | G2: =SQRT((C3^2/8)*(((1/C6)/(2*C11))^2+(PI()/C5)^2)) -> 335.86395 | I2: phase difference | K2: =ASIN((C3*1/C6)/(4*SQRT(2)*C11*G2)) -> 0.12564802 | M2: =K2*180/PI() -> 7.1991015
A3: Vo | B3: output voltage | C3: 1000 | E3: Is, rms | F3: secondary side current, rms | G3: =G2 -> 335.86395 | I3: time difference | K3: =K2/(2*PI()*C6) -> 7.1419658e-07
A4: Io | B4: output current | C4: =C2/C3 -> 300 | E4: Ip, pk | F4: primary side current, pk | G4: =G2*SQRT(2) -> 474.98335 | O4: =ASIN((C3*1/C6)/(4*SQRT(2)*C11*G2)) -> 0.12564802
A5: Ro | B5: output resistance | C5: =C3/C4 -> 3.3333333 | E5: Is, pk | F5: secondary side current, pk | G5: =G3*SQRT(2) -> 474.98335
A6: fs | B6: switching frequency | C6: 28000 | E6: dt | F6: deadtime | K6: =4*2*PI()*C6*10^-7 -> 0.070371675
A7: fr | B7: resonant frequency | C7: 30000
A8: phi | B8: phase diff
A9: Transformer Parameters
A10: number of turns | B10: n | C10: =C11*C13/(C12*E11) -> 7.5 | D10: actual chosen | E10: 8
A11: magnetizing inductance | B11: Lm | C11: 0.00015 | D11: max saturation flux density | E11: 0.4
A12: area of center leg | B12: Ac | C12: =C23 -> 0.025 | F12: =1/3*10^-4 -> 3.3333333e-05
A13: Ipri, pk | B13: Ip, pk (estimate) | C13: 500 | E13: =10^2*2500*4*PI()*10^-7*C12/0.12 -> 0.065449847 | Q13: =1/30000/4 -> 8.3333333e-06
A14: Area Product | B14: theoretical | D14: actual
A15: AwAc | B15: =B16*B17 -> 29462783 | D15: =D23*220*26 -> 143000000 | L15: =145944*3 -> 437832
A16: Aw | B16: =(10/(5*0.9)*(500/SQRT(2))*2) -> 1571.3484
A17: Ac | B17: =(C11*500)/(10*0.4)*10^6 -> 18750
A19: Transformer Dimensions | D19: mm | G19: path modelling
A20: nCore | B20: number of cores | C20: 5 | F20: half cross section | G20: =D30/2+B31+B32 -> 5.5 | I20: #1 | J20: =D22+1*G21 -> 111
A21: L_c | B21: length of center leg | C21: =250/1000 -> 0.25 | D21: =1000*C21 -> 250 | F21: whole cross section | G21: =G20*2 -> 11 | I21: #2 | J21: =D21+2*G21 -> 272
A22: W_c | B22: width of center leg | C22: =100/1000 -> 0.1 | D22: =1000*C22 -> 100 | I22: #3 | J22: =D22+G21*2 -> 122
A23: A_c | B23: area of center leg | C23: =C21*C22 -> 0.025 | D23: =1000*C23*1000 -> 25000 | I23: #4 | J23: =D21+G21*4 -> 294
A24: A_l | B24: area of right and left leg | C24: =C23/2 -> 0.0125 | D24: =1000*C24*1000 -> 12500 | I24: #5 | J24: =D22+3*G21+G21 -> 144
A25: L_l | B25: length of right and left leg | C25: =C21 -> 0.25 | D25: =1000*C25 -> 250 | I25: #6 | J25: =D21+6*G21 -> 316
A26: W_l | B26: width of right and left leg | C26: =C22/2 -> 0.05 | D26: =1000*C26 -> 50 | I26: #7 | J26: =D22+6*G21 -> 166
I27: #8 | J27: =D21+8*G21 -> 338
A28: Wire Dimensions | I28: #9
A29: Wire Height | B29: 12.5 | D29: 20 | E29: 25 | I29: #10
A30: Wire Width | B30: 8 | D30: 5 | E30: 4 | I30: #11
A31: wire coating thickness | B31: 2 | I31: #12
A32: insulation thickness | B32: 1 | I32: #13
I33: #14
I34: #15
A37: air gap | B37: =(E10^2*B40*B41*C23^2/C11-C23*(B38+B39))*1/((B41-1)*2*C23)*10^3 -> 6.5074673
A38: lmc | B38: 0.36
A39: lmo | B39: 0.626
A40: uo | B40: =4*PI()*10^-7 -> 1.2566371e-06
A41: ur | B41: 2500

Sheet solidworks variables list
A1: nTurns | B1: 10
A2: nCore | B2: 5
A3: nGap | B3: nCore - 1
A4: totalCoreLength | B4: 250
A5: airGap | B5: 10
A6: Wire Face
A7: wireWidth | B7: 5
A8: wireHeight | B8: 20
A9: coatingThickness | B9: 2
A10: insulationThickness | B10: 1
A11: wireDistance | B11: 2*(coatingThickness+insulationThickness)
A12: centerDistance | B12: (wireHeight + coating Thickness * 2 + insulationThickness * 2) /2
A14: Transformer Core (whole piece) | D14: Transformer Core (Gap Piece)
A15: centerLegWidth | B15: 100
A16: outerLegWidth | B16: centerLegWidth/2
A17: wireToCore | B17: 10
A18: coreWindowHeight | B18: 8
A19: coreWindowWidth | B19: (wireWidth + coating Thickness * 2 + insulationThickness * 2) *2*nTurns
A20: coreToCoreGapLength | B20: (totalCoreLength - 5 * coreLength)/(nGap)
A21: coreWidth | B21: centerLegWidth + 2*(coreWindowWidth + outerLegWidth)
A22: coreLength | B22: 49
A24: Outer Core Templates
A25: outerCoreLength | B25: 176
